Workbook
Name Slicer_Genre: #N/A
Name Slicer_Platform: #N/A
Name Slicer_Publisher: #N/A

Sheet Dashboard
Z1: Total count of games
Z2: =COUNTA(GmsTbl[Game_Title]) -> 1000
B3: TOTAL GAMES | E3: TOTAL SALES | H3: AVERAGE SALES | K3: TOP GAME | N3: TOP GENRE | Q3: TOP PLATFORM | Z3: Sum of sales
B4: =COUNTA(GmsTbl[Game_Title]) -> 1000 | E4: =SUM(GmsTbl[Global_Sales_Millions]) -> 898.52 | H4: =AVERAGE(GmsTbl[Global_Sales_Millions]) -> 0.89852 | K4: =INDEX(GmsTbl[Game_Title],MATCH(MAX(GmsTbl[Global_Sales_Millions]),GmsTbl[Global_Sales_Millions],0)) -> World Adventure 495 | N4: =INDEX('Pivot Tables'!D3:D12,MATCH(MAX('Pivot Tables'!E3:E12),'Pivot Tables'!E3:E12,0)) -> #N/A | Q4: =INDEX('Pivot Tables'!A3:A9,MATCH(MAX('Pivot Tables'!B3:B9),'Pivot Tables'!B3:B9,0)) -> #N/A | Z4: =SUM(GmsTbl[Global_Sales_Millions]) -> 898.52
Z5: average Sales
Z6: =GETPIVOTDATA("Global_Sales_Millions",'Pivot Tables'!$J$12) -> 0.89852
Z7: Top Game
Z8: ='Pivot Tables'!K38 -> World Adventure 495
Z9: TopGener
Z10: ='Pivot Tables'!D88 -> 0

Sheet Pivot Tables
A3: #VALUE!
N4: Count of Game_Title
N5: 1000
J9: Sum of Global_Sales_Millions
J10: 898.52
J12: Average of Global_Sales_Millions
J13: 0.89852
A15: Sum of Global_Sales_Millions | B15: Column Labels
A16: Row Labels | B16: Action | C16: Adventure | D16: Fighting | E16: Platform | F16: Racing | G16: RPG | H16: Shooter | I16: Simulation | J16: Sports | K16: Strategy | L16: Grand Total
A17: PS Vita | B17: 6.16 | C17: 3.91 | D17: 7.11 | E17: 4.46 | F17: 6.95 | G17: 2.84 | H17: 9.14 | I17: 7.89 | J17: 10.13 | K17: 9.8 | L17: 68.39
A18: PS1 | B18: 7.4 | C18: 3.51 | D18: 8.64 | E18: 7.36 | F18: 12.88 | G18: 8.14 | H18: 17.81 | I18: 11.61 | J18: 8.53 | K18: 10.22 | L18: 96.1
A19: PS2 | B19: 11.71 | C19: 11.47 | D19: 15.85 | E19: 11.03 | F19: 11.91 | G19: 16.56 | H19: 10.79 | I19: 19.05 | J19: 23.59 | K19: 15.72 | L19: 147.68
A20: PS3 | B20: 28.51 | C20: 22.32 | D20: 20.84 | E20: 11.45 | F20: 13.08 | G20: 12.09 | H20: 5.7 | I20: 14.74 | J20: 16.57 | K20: 14.95 | L20: 160.25
A21: PS4 | B21: 40.77 | C21: 30.28 | D21: 5.19 | E21: 13.6 | F21: 5.82 | G21: 11.47 | H21: 20.18 | I21: 20.77 | J21: 34.02 | K21: 14.51 | L21: 196.61
A22: PS5 | B22: 21.09 | C22: 15.12 | D22: 10.85 | E22: 8.03 | F22: 9.74 | G22: 15.03 | H22: 17.56 | I22: 3.39 | J22: 18.17 | K22: 11 | L22: 129.98
A23: PSP | B23: 4.48 | C23: 8.11 | D23: 10.75 | E23: 16.64 | F23: 4.17 | G23: 9.64 | H23: 12.62 | I23: 8.2 | J23: 17.59 | K23: 7.31 | L23: 99.51
A24: Grand Total | B24: 120.12 | C24: 94.72 | D24: 79.23 | E24: 72.57 | F24: 64.55 | G24: 75.77 | H24: 93.8 | I24: 85.65 | J24: 128.6 | K24: 83.51 | L24: 898.52
A27: Row Labels | B27: Sum of North_America_Sales_Millions | C27: Sum of Europe_Sales_Millions | D27: Sum of Japan_Sales_Millions | E27: Sum of Other_Sales_Millions
A28: PS Vita | B28: 30.91 | C28: 18.02 | D28: 8.14 | E28: 11.32
A29: PS1 | B29: 43.34 | C29: 26.14 | D29: 11.59 | E29: 15.03
A30: PS2 | B30: 67.41 | C30: 40.13 | D30: 18.41 | E30: 21.73
A31: PS3 | B31: 71.69 | C31: 44.11 | D31: 19.25 | E31: 25.2
A32: PS4 | B32: 88.93 | C32: 53.33 | D32: 24.62 | E32: 29.73
A33: PS5 | B33: 57.59 | C33: 35.57 | D33: 16.47 | E33: 20.35
A34: PSP | B34: 44.01 | C34: 27.31 | D34: 11.86 | E34: 16.33
A35: Grand Total | B35: 403.88 | C35: 244.61 | D35: 110.34 | E35: 139.69
K37: Row Labels | L37: Sum of Global_Sales_Millions
A38: Sum of Global_Sales_Millions | B38: Column Labels | K38: World Adventure 495 | L38: 15.04
A39: Row Labels | B39: PS Vita | C39: PS1 | D39: PS2 | E39: PS3 | F39: PS4 | G39: PS5 | H39: PSP | I39: Grand Total | K39: Dark Football 728 | L39: 13.3
A40: 1995 | C40: 8.59 | I40: 8.59 | K40: World Football 100 | L40: 10.61
A41: 1996 | C41: 15.94 | I41: 15.94 | K41: God of War | L41: 10.18
A42: 1997 | C42: 15.5 | I42: 15.5 | K42: Chronicles Strike 750 | L42: 10.02
A43: 1998 | C43: 17.48 | I43: 17.48 | K43: Chronicles Kingdom 424 | L43: 7.21
A44: 1999 | C44: 19.95 | I44: 19.95 | K44: Dark Kingdom 647 | L44: 7.07
A45: 2000 | C45: 18.64 | D45: 15.38 | I45: 34.02 | K45: Pro Arena 841 | L45: 6
A46: 2001 | D46: 21.89 | I46: 21.89 | K46: Warriors War 194 | L46: 5.86
A47: 2002 | D47: 19.69 | I47: 19.69 | K47: Legends Football 960 | L47: 5.6
A48: 2003 | D48: 18.94 | I48: 18.94 | K48: World Football 696 | L48: 5.43
A49: 2004 | D49: 15.79 | H49: 8.86 | I49: 24.65 | K49: Extreme Quest 255 | L49: 4.77
A50: 2005 | D50: 27.66 | H50: 4.29 | I50: 31.95 | K50: Extreme Arena 783 | L50: 4.69
...

Sheet PlayStation Games
A1: Game_ID | B1: Game_Title | C1: Platform | D1: Genre | E1: Publisher | F1: Release_Year | G1: Critic_Rating | H1: Global_Sales_Millions | I1: North_America_Sales_Millions | J1: Europe_Sales_Millions | K1: Japan_Sales_Millions | L1: Other_Sales_Millions | M1: Sales_Category | N1: Ratings by Category
A2: 1 | B2: Grand Theft Auto V | C2: PS3 | D2: Action | E2: Take-Two Interactive | F2: 2013 | G2: 97 | H2: 0.74 | I2: 0.3 | J2: 0.17 | K2: 0.12 | L2: 0.15 | M2: Medium | N2: {=_xlfn.IFS(G2>=90,"Excellent",G2>=80,"Good",G2>=70,"Average",G2<70,"Poor")} -> Excellent | P2: id | Q2: title
A3: 2 | B3: God of War | C3: PS4 | D3: Action | E3: Sony Computer Entertainment | F3: 2018 | G3: 94 | H3: 10.18 | I3: 3.74 | J3: 2.68 | K3: 0.55 | L3: 3.21 | M3: Blockbuster | N3: {=_xlfn.IFS(G3>=90,"Excellent",G3>=80,"Good",G3>=70,"Average",G3<70,"Poor")} -> Excellent | P3: 1
A4: 3 | B4: God of War Ragnarök | C4: PS5 | D4: Action | E4: Sony Computer Entertainment | F4: 2022 | G4: 94 | H4: 0.31 | I4: 0.11 | J4: 0.07 | K4: 0.05 | L4: 0.08 | M4: Low | N4: {=_xlfn.IFS(G4>=90,"Excellent",G4>=80,"Good",G4>=70,"Average",G4<70,"Poor")} -> Excellent
A5: 4 | B5: The Last of Us | C5: PS3 | D5: Action | E5: Sony Computer Entertainment | F5: 2013 | G5: 95 | H5: 0.64 | I5: 0.3 | J5: 0.21 | K5: 0.03 | L5: 0.1 | M5: Medium | N5: {=_xlfn.IFS(G5>=90,"Excellent",G5>=80,"Good",G5>=70,"Average",G5<70,"Poor")} -> Excellent
A6: 5 | B6: The Last of Us Part II | C6: PS4 | D6: Action | E6: Sony Computer Entertainment | F6: 2020 | G6: 93 | H6: 3.87 | I6: 1.62 | J6: 0.86 | K6: 0.75 | L6: 0.64 | M6: High | N6: {=_xlfn.IFS(G6>=90,"Excellent",G6>=80,"Good",G6>=70,"Average",G6<70,"Poor")} -> Excellent
A7: 6 | B7: Gran Turismo 7 | C7: PS5 | D7: Racing | E7: Sony Computer Entertainment | F7: 2022 | G7: 87 | H7: 0.56 | I7: 0.21 | J7: 0.18 | K7: 0.08 | L7: 0.09 | M7: Medium | N7: {=_xlfn.IFS(G7>=90,"Excellent",G7>=80,"Good",G7>=70,"Average",G7<70,"Poor")} -> Good
A8: 7 | B8: Gran Turismo 4 | C8: PS2 | D8: Racing | E8: Sony Computer Entertainment | F8: 2004 | G8: 89 | H8: 3.83 | I8: 1.75 | J8: 1.33 | K8: 0.41 | L8: 0.34 | M8: High | N8: {=_xlfn.IFS(G8>=90,"Excellent",G8>=80,"Good",G8>=70,"Average",G8<70,"Poor")} -> Good
A9: 8 | B9: Uncharted 4: A Thief's End | C9: PS4 | D9: Adventure | E9: Sony Computer Entertainment | F9: 2016 | G9: 93 | H9: 1.3 | I9: 0.62 | J9: 0.43 | K9: 0.18 | L9: 0.07 | M9: Medium | N9: {=_xlfn.IFS(G9>=90,"Excellent",G9>=80,"Good",G9>=70,"Average",G9<70,"Poor")} -> Excellent
A10: 9 | B10: Spider-Man | C10: PS4 | D10: Action | E10: Sony Computer Entertainment | F10: 2018 | G10: 87 | H10: 1.13 | I10: 0.45 | J10: 0.28 | K10: 0.07 | L10: 0.33 | M10: Medium | N10: {=_xlfn.IFS(G10>=90,"Excellent",G10>=80,"Good",G10>=70,"Average",G10<70,"Poor")} -> Good
A11: 10 | B11: Spider-Man: Miles Morales | C11: PS5 | D11: Action | E11: Sony Computer Entertainment | F11: 2020 | G11: 85 | H11: 0.47 | I11: 0.19 | J11: 0.14 | K11: 0.05 | L11: 0.09 | M11: Low | N11: {=_xlfn.IFS(G11>=90,"Excellent",G11>=80,"Good",G11>=70,"Average",G11<70,"Poor")} -> Good
A12: 11 | B12: Horizon Zero Dawn | C12: PS4 | D12: RPG | E12: Sony Computer Entertainment | F12: 2017 | G12: 89 | H12: 0.63 | I12: 0.25 | J12: 0.21 | K12: 0.09 | L12: 0.08 | M12: Medium | N12: {=_xlfn.IFS(G12>=90,"Excellent",G12>=80,"Good",G12>=70,"Average",G12<70,"Poor")} -> Good
A13: 12 | B13: Ghost of Tsushima | C13: PS4 | D13: Action | E13: Sony Computer Entertainment | F13: 2020 | G13: 83 | H13: 0.99 | I13: 0.49 | J13: 0.22 | K13: 0.11 | L13: 0.17 | M13: Medium | N13: {=_xlfn.IFS(G13>=90,"Excellent",G13>=80,"Good",G13>=70,"Average",G13<70,"Poor")} -> Good
A14: 13 | B14: Bloodborne | C14: PS4 | D14: RPG | E14: Sony Computer Entertainment | F14: 2015 | G14: 92 | H14: 1.07 | I14: 0.55 | J14: 0.34 | K14: 0.09 | L14: 0.09 | M14: Medium | N14: {=_xlfn.IFS(G14>=90,"Excellent",G14>=80,"Good",G14>=70,"Average",G14<70,"Poor")} -> Excellent
A15: 14 | B15: Final Fantasy VII Remake | C15: PS4 | D15: RPG | E15: Square Enix | F15: 2020 | G15: 87 | H15: 0.28 | I15: 0.11 | J15: 0.06 | K15: 0.05 | L15: 0.06 | M15: Low | N15: {=_xlfn.IFS(G15>=90,"Excellent",G15>=80,"Good",G15>=70,"Average",G15<70,"Poor")} -> Good
... A1001: 1000 | B1001: Pro Adventure 1000 | C1001: PS3 | D1001: Platform | E1001: Sony Computer Entertainment | F1001: 2009 | G1001: 65 | H1001: 2.69 | I1001: 1.44 | J1001: 0.74 | K1001: 0.51 | L1001: 0 | M1001: High | N1001: {=_xlfn.IFS(G1001>=90,"Excellent",G1001>=80,"Good",G1001>=70,"Average",G1001<70,"Poor")} -> Poor

Sheet OG Dataset
A1: Game_ID | B1: Game_Title | C1: Platform | D1: Genre | E1: Publisher | F1: Release_Year | G1: Critic_Rating | H1: Global_Sales_Millions | I1: North_America_Sales_Millions | J1: Europe_Sales_Millions | K1: Japan_Sales_Millions | L1: Other_Sales_Millions | M1: Sales_Category | N1: Rating_Category
A2: 1 | B2: Grand Theft Auto V | C2: PS3 | D2: Action | E2: Take-Two Interactive | F2: 2013 | G2: 97 | H2: 0.74 | I2: 0.3 | J2: 0.17 | K2: 0.12 | L2: 0.15 | M2: Medium | N2: Excellent
A3: 2 | B3: God of War | C3: PS4 | D3: Action | E3: Sony Computer Entertainment | F3: 2018 | G3: 94 | H3: 10.18 | I3: 3.74 | J3: 2.68 | K3: 0.55 | L3: 3.21 | M3: Blockbuster | N3: Excellent
A4: 3 | B4: God of War Ragnarök | C4: PS5 | D4: Action | E4: Sony Computer Entertainment | F4: 2022 | G4: 94 | H4: 0.31 | I4: 0.11 | J4: 0.07 | K4: 0.05 | L4: 0.08 | M4: Low | N4: Excellent
A5: 4 | B5: The Last of Us | C5: PS3 | D5: Action | E5: Sony Computer Entertainment | F5: 2013 | G5: 95 | H5: 0.64 | I5: 0.3 | J5: 0.21 | K5: 0.03 | L5: 0.1 | M5: Medium | N5: Excellent
A6: 5 | B6: The Last of Us Part II | C6: PS4 | D6: Action | E6: Sony Computer Entertainment | F6: 2020 | G6: 93 | H6: 3.87 | I6: 1.62 | J6: 0.86 | K6: 0.75 | L6: 0.64 | M6: High | N6: Excellent
A7: 6 | B7: Gran Turismo 7 | C7: PS5 | D7: Racing | E7: Sony Computer Entertainment | F7: 2022 | G7: 87 | H7: 0.56 | I7: 0.21 | J7: 0.18 | K7: 0.08 | L7: 0.09 | M7: Medium | N7: Good
A8: 7 | B8: Gran Turismo 4 | C8: PS2 | D8: Racing | E8: Sony Computer Entertainment | F8: 2004 | G8: 89 | H8: 3.83 | I8: 1.75 | J8: 1.33 | K8: 0.41 | L8: 0.34 | M8: High | N8: Good
A9: 8 | B9: Uncharted 4: A Thief's End | C9: PS4 | D9: Adventure | E9: Sony Computer Entertainment | F9: 2016 | G9: 93 | H9: 1.3 | I9: 0.62 | J9: 0.43 | K9: 0.18 | L9: 0.07 | M9: Medium | N9: Excellent
A10: 9 | B10: Spider-Man | C10: PS4 | D10: Action | E10: Sony Computer Entertainment | F10: 2018 | G10: 87 | H10: 1.13 | I10: 0.45 | J10: 0.28 | K10: 0.07 | L10: 0.33 | M10: Medium | N10: Good
A11: 10 | B11: Spider-Man: Miles Morales | C11: PS5 | D11: Action | E11: Sony Computer Entertainment | F11: 2020 | G11: 85 | H11: 0.47 | I11: 0.19 | J11: 0.14 | K11: 0.05 | L11: 0.09 | M11: Low | N11: Good
A12: 11 | B12: Horizon Zero Dawn | C12: PS4 | D12: RPG | E12: Sony Computer Entertainment | F12: 2017 | G12: 89 | H12: 0.63 | I12: 0.25 | J12: 0.21 | K12: 0.09 | L12: 0.08 | M12: Medium | N12: Good
A13: 12 | B13: Ghost of Tsushima | C13: PS4 | D13: Action | E13: Sony Computer Entertainment | F13: 2020 | G13: 83 | H13: 0.99 | I13: 0.49 | J13: 0.22 | K13: 0.11 | L13: 0.17 | M13: Medium | N13: Good
... A1001: 1000 | B1001: Pro Adventure 1000 | C1001: PS3 | D1001: Platform | E1001: Sony Computer Entertainment | F1001: 2009 | G1001: 65 | H1001: 2.69 | I1001: 1.44 | J1001: 0.74 | K1001: 0.51 | L1001: 0 | M1001: High | N1001: Poor

Sheet Reference
A1: Platform | B1: Genre | C1: Publisher
A2: PS1 | B2: Action | C2: Sony Computer Entertainment
A3: PS2 | B3: Adventure | C3: Electronic Arts
A4: PS3 | B4: RPG | C4: Ubisoft
A5: PS4 | B5: Sports | C5: Activision
A6: PS5 | B6: Shooter | C6: Bandai Namco
A7: PSP | B7: Racing | C7: Capcom
A8: PS Vita | B8: Fighting | C8: Square Enix
B9: Strategy | C9: Take-Two Interactive
B10: Simulation | C10: Konami
B11: Platform | C11: Bethesda
